<!DOCTYPE html>
<html lang="en">
<head>
    <meta charset="UTF-8">
    <meta name="viewport" content="width=device-width, initial-scale=1.0">
    <title>Document</title>
</head>
<body>
    <script>
        /* 1. Create a function called "fetchPokemon" that returns a Promise that resolves with the value: {data: (name: "Pickachu", power: 20}} after 2 seconds

        2. Print out "Program starting..."

        A

        3. Create an async function that uses await to wait for the data to comes back from "fetch Pokemon" then log out the data

        4. Call the async function you created

        5. Log out "Program complete!"

        After your're done the above:

        6. Change "fetchPokemon" to reject after 2 seconds instead with a new Error Object with the message "Danger, danger! I

        7. How can you modify your async function to catch this error? */ 

        /*function fetchPokemon() {
            return new Promise((resolve,reject) => {
                setTimeout(() => {
                    resolve({data: {name: "Pickachu", power: 20}});
                })
            }, 2000);
        };

        console.log("Program starting...");

        async function usePokemon() {
            const data = await fetchPokemon();
            console.log(data);
        };
        
        usePokemon();
        
        console.log("Program complete!"); */


        function fetchPokemon() {
            return new Promise((resolve,reject) => {
                setTimeout(() => {
                    reject(new Error('Danger, danger!'));
                })
            }, 2000);
        };

        console.log("Program starting...");

        async function usePokemon() {
            const data = await fetchPokemon();
            console.log(data);
        };
        
        usePokemon();

        console.log("Program complete!");


    </script>
</body>
</html>
